python2 mlfq.py  -j 2 -n 2 -M 0 -m 15 -s 963 -c

Here is the list of inputs:
OPTIONS jobs 2
OPTIONS queues 2
OPTIONS allotments for queue  1 is   1
OPTIONS quantum length for queue  1 is  10
OPTIONS allotments for queue  0 is   1
OPTIONS quantum length for queue  0 is  10
OPTIONS boost 0
OPTIONS ioTime 5
OPTIONS stayAfterIO False
OPTIONS iobump False


For each job, three defining characteristics are given:
  startTime : at what time does the job enter the system
  runTime   : the total CPU time needed by the job to finish
  ioFreq    : every ioFreq time units, the job issues an I/O
              (the I/O takes ioTime units to complete)

Job List:
  Job  0: startTime   0 - runTime  14 - ioFreq   0
  Job  1: startTime   0 - runTime   5 - ioFreq   0


Execution Trace:

[ time 0 ] JOB BEGINS by JOB 0
[ time 0 ] JOB BEGINS by JOB 1
[ time 0 ] Run JOB 0 at PRIORITY 1 [ TICKS 9 ALLOT 1 TIME 13 (of 14) ]
[ time 1 ] Run JOB 0 at PRIORITY 1 [ TICKS 8 ALLOT 1 TIME 12 (of 14) ]
[ time 2 ] Run JOB 0 at PRIORITY 1 [ TICKS 7 ALLOT 1 TIME 11 (of 14) ]
[ time 3 ] Run JOB 0 at PRIORITY 1 [ TICKS 6 ALLOT 1 TIME 10 (of 14) ]
[ time 4 ] Run JOB 0 at PRIORITY 1 [ TICKS 5 ALLOT 1 TIME 9 (of 14) ]
[ time 5 ] Run JOB 0 at PRIORITY 1 [ TICKS 4 ALLOT 1 TIME 8 (of 14) ]
[ time 6 ] Run JOB 0 at PRIORITY 1 [ TICKS 3 ALLOT 1 TIME 7 (of 14) ]
[ time 7 ] Run JOB 0 at PRIORITY 1 [ TICKS 2 ALLOT 1 TIME 6 (of 14) ]
[ time 8 ] Run JOB 0 at PRIORITY 1 [ TICKS 1 ALLOT 1 TIME 5 (of 14) ]
[ time 9 ] Run JOB 0 at PRIORITY 1 [ TICKS 0 ALLOT 1 TIME 4 (of 14) ]
[ time 10 ] Run JOB 1 at PRIORITY 1 [ TICKS 9 ALLOT 1 TIME 4 (of 5) ]
[ time 11 ] Run JOB 1 at PRIORITY 1 [ TICKS 8 ALLOT 1 TIME 3 (of 5) ]
[ time 12 ] Run JOB 1 at PRIORITY 1 [ TICKS 7 ALLOT 1 TIME 2 (of 5) ]
[ time 13 ] Run JOB 1 at PRIORITY 1 [ TICKS 6 ALLOT 1 TIME 1 (of 5) ]
[ time 14 ] Run JOB 1 at PRIORITY 1 [ TICKS 5 ALLOT 1 TIME 0 (of 5) ]
[ time 15 ] FINISHED JOB 1
[ time 15 ] Run JOB 0 at PRIORITY 0 [ TICKS 9 ALLOT 1 TIME 3 (of 14) ]
[ time 16 ] Run JOB 0 at PRIORITY 0 [ TICKS 8 ALLOT 1 TIME 2 (of 14) ]
[ time 17 ] Run JOB 0 at PRIORITY 0 [ TICKS 7 ALLOT 1 TIME 1 (of 14) ]
[ time 18 ] Run JOB 0 at PRIORITY 0 [ TICKS 6 ALLOT 1 TIME 0 (of 14) ]
[ time 19 ] FINISHED JOB 0

Final statistics:
  Job  0: startTime   0 - response   0 - turnaround  19
  Job  1: startTime   0 - response  10 - turnaround  15

  Avg  1: startTime n/a - response 5.00 - turnaround 17.00